<?xml version="1.0" encoding="utf-8"?>
<!-- This URDF was automatically created by SolidWorks to URDF Exporter! Originally created by Stephen Brawner (brawner@gmail.com) 
     Commit Version: 1.6.0-1-g15f4949  Build Version: 1.6.7594.29634
     For more information, please see http://wiki.ros.org/sw_urdf_exporter -->
<robot
  name="assem_urdf.SLDASM">
  <link
    name="base_link">
    <inertial>
      <origin
        xyz="3.9509E-17 0.16127 0.0079243"
        rpy="0 0 0" />
      <mass
        value="0.4453" />
      <inertia
        ixx="0.0055803"
        ixy="1.2165E-18"
        ixz="-4.5088E-20"
        iyy="0.00058228"
        iyz="4.2851E-05"
        izz="0.005728" />
    </inertial>
    <visual>
      <origin
        xyz="0 0 0"
        rpy="0 0 0" />
      <geometry>
        <mesh
          filename="package://assem_urdf.SLDASM/meshes/base_link.STL" />
      </geometry>
      <material
        name="">
        <color
          rgba="0.79216 0.81961 0.93333 1" />
      </material>
    </visual>
    <collision>
      <origin
        xyz="0 0 0"
        rpy="0 0 0" />
      <geometry>
        <mesh
          filename="package://assem_urdf.SLDASM/meshes/base_link.STL" />
      </geometry>
    </collision>
  </link>
  <link
    name="FR_Hip0_link">
    <inertial>
      <origin
        xyz="-0.00060544 6.9389E-18 -0.034287"
        rpy="0 0 0" />
      <mass
        value="0.067785" />
      <inertia
        ixx="2.6247E-05"
        ixy="-4.0036E-22"
        ixz="5.961E-08"
        iyy="3.2333E-05"
        iyz="2.7045E-21"
        izz="1.3621E-05" />
    </inertial>
    <visual>
      <origin
        xyz="0 0 0"
        rpy="0 0 0" />
      <geometry>
        <mesh
          filename="package://assem_urdf.SLDASM/meshes/FR_Hip0_link.STL" />
      </geometry>
      <material
        name="">
        <color
          rgba="0.79216 0.81961 0.93333 1" />
      </material>
    </visual>
    <collision>
      <origin
        xyz="0 0 0"
        rpy="0 0 0" />
      <geometry>
        <mesh
          filename="package://assem_urdf.SLDASM/meshes/FR_Hip0_link.STL" />
      </geometry>
    </collision>
  </link>
  <joint
    name="FR_Hip0_joint"
    type="revolute">
    <origin
      xyz="-0.04 0.0825 -0.01025"
      rpy="1.5708 0 -3.1416" />
    <parent
      link="base_link" />
    <child
      link="FR_Hip0_link" />
    <axis
      xyz="0 0 1" />
    <limit
      lower="0"
      upper="0"
      effort="0"
      velocity="0" />
  </joint>
  <link
    name="FR_Hip1_link">
    <inertial>
      <origin
        xyz="-0.10072 0.02657 -0.018148"
        rpy="0 0 0" />
      <mass
        value="0.0064106" />
      <inertia
        ixx="1.1008E-06"
        ixy="1.0884E-06"
        ixz="-2.5725E-06"
        iyy="8.476E-06"
        iyz="3.699E-07"
        izz="7.7954E-06" />
    </inertial>
    <visual>
      <origin
        xyz="0 0 0"
        rpy="0 0 0" />
      <geometry>
        <mesh
          filename="package://assem_urdf.SLDASM/meshes/FR_Hip1_link.STL" />
      </geometry>
      <material
        name="">
        <color
          rgba="0.79216 0.81961 0.93333 1" />
      </material>
    </visual>
    <collision>
      <origin
        xyz="0 0 0"
        rpy="0 0 0" />
      <geometry>
        <mesh
          filename="package://assem_urdf.SLDASM/meshes/FR_Hip1_link.STL" />
      </geometry>
    </collision>
  </link>
  <joint
    name="FR_Hip1_joint"
    type="revolute">
    <origin
      xyz="0.01 0.048079 -0.038176"
      rpy="1.526 -0.12836 1.9075" />
    <parent
      link="FR_Hip0_link" />
    <child
      link="FR_Hip1_link" />
    <axis
      xyz="0.32763 0 -0.94481" />
    <limit
      lower="0"
      upper="0"
      effort="0"
      velocity="0" />
  </joint>
  <link
    name="FR_Hip2_link">
    <inertial>
      <origin
        xyz="0.0055236 -0.049448 0.0037719"
        rpy="0 0 0" />
      <mass
        value="0.0025827" />
      <inertia
        ixx="3.3013E-06"
        ixy="3.662E-07"
        ixz="-3.2537E-09"
        iyy="6.3909E-08"
        iyz="2.9127E-08"
        izz="3.3606E-06" />
    </inertial>
    <visual>
      <origin
        xyz="0 0 0"
        rpy="0 0 0" />
      <geometry>
        <mesh
          filename="package://assem_urdf.SLDASM/meshes/FR_Hip2_link.STL" />
      </geometry>
      <material
        name="">
        <color
          rgba="0.79216 0.81961 0.93333 1" />
      </material>
    </visual>
    <collision>
      <origin
        xyz="0 0 0"
        rpy="0 0 0" />
      <geometry>
        <mesh
          filename="package://assem_urdf.SLDASM/meshes/FR_Hip2_link.STL" />
      </geometry>
    </collision>
  </link>
  <joint
    name="FR_Hip2_joint"
    type="revolute">
    <origin
      xyz="-0.16506 0.035756 -0.037656"
      rpy="0.32702 0.068144 -1.7689" />
    <parent
      link="FR_Hip1_link" />
    <child
      link="FR_Hip2_link" />
    <axis
      xyz="0 0 -1" />
    <limit
      lower="0"
      upper="0"
      effort="0"
      velocity="0" />
  </joint>
  <link
    name="FL_Hip3_link">
    <inertial>
      <origin
        xyz="-0.00060544 5.2042E-18 -0.034287"
        rpy="0 0 0" />
      <mass
        value="0.067785" />
      <inertia
        ixx="2.6247E-05"
        ixy="-1.6025E-22"
        ixz="5.961E-08"
        iyy="3.2333E-05"
        iyz="-6.233E-22"
        izz="1.3621E-05" />
    </inertial>
    <visual>
      <origin
        xyz="0 0 0"
        rpy="0 0 0" />
      <geometry>
        <mesh
          filename="package://assem_urdf.SLDASM/meshes/FL_Hip3_link.STL" />
      </geometry>
      <material
        name="">
        <color
          rgba="0.79216 0.81961 0.93333 1" />
      </material>
    </visual>
    <collision>
      <origin
        xyz="0 0 0"
        rpy="0 0 0" />
      <geometry>
        <mesh
          filename="package://assem_urdf.SLDASM/meshes/FL_Hip3_link.STL" />
      </geometry>
    </collision>
  </link>
  <joint
    name="FL_Hip3_joint"
    type="revolute">
    <origin
      xyz="0.04 0.0825 -0.01025"
      rpy="-1.5708 0 0" />
    <parent
      link="base_link" />
    <child
      link="FL_Hip3_link" />
    <axis
      xyz="0 0 1" />
    <limit
      lower="0"
      upper="0"
      effort="0"
      velocity="0" />
  </joint>
  <link
    name="FL_Hip4_link">
    <inertial>
      <origin
        xyz="0.041114 0.020928 -0.0077205"
        rpy="0 0 0" />
      <mass
        value="0.0064106" />
      <inertia
        ixx="1.8319E-06"
        ixy="-3.4621E-06"
        ixz="4.6782E-08"
        iyy="6.8709E-06"
        iyz="2.3813E-08"
        izz="8.6695E-06" />
    </inertial>
    <visual>
      <origin
        xyz="0 0 0"
        rpy="0 0 0" />
      <geometry>
        <mesh
          filename="package://assem_urdf.SLDASM/meshes/FL_Hip4_link.STL" />
      </geometry>
      <material
        name="">
        <color
          rgba="0.79216 0.81961 0.93333 1" />
      </material>
    </visual>
    <collision>
      <origin
        xyz="0 0 0"
        rpy="0 0 0" />
      <geometry>
        <mesh
          filename="package://assem_urdf.SLDASM/meshes/FL_Hip4_link.STL" />
      </geometry>
    </collision>
  </link>
  <joint
    name="FL_Hip4_joint"
    type="revolute">
    <origin
      xyz="0.018132 0.0095637 -0.02555"
      rpy="-1.5708 -0.47085 1.5708" />
    <parent
      link="FL_Hip3_link" />
    <child
      link="FL_Hip4_link" />
    <axis
      xyz="0 0 1" />
    <limit
      lower="0"
      upper="0"
      effort="0"
      velocity="0" />
  </joint>
  <link
    name="FL_Hip5_link">
    <inertial>
      <origin
        xyz="0 -0.049755 -0.0037719"
        rpy="0 0 0" />
      <mass
        value="0.0025827" />
      <inertia
        ixx="3.3422E-06"
        ixy="-1.3183E-22"
        ixz="-1.7916E-24"
        iyy="2.3002E-08"
        iyz="-2.9308E-08"
        izz="3.3606E-06" />
    </inertial>
    <visual>
      <origin
        xyz="0 0 0"
        rpy="0 0 0" />
      <geometry>
        <mesh
          filename="package://assem_urdf.SLDASM/meshes/FL_Hip5_link.STL" />
      </geometry>
      <material
        name="">
        <color
          rgba="0.79216 0.81961 0.93333 1" />
      </material>
    </visual>
    <collision>
      <origin
        xyz="0 0 0"
        rpy="0 0 0" />
      <geometry>
        <mesh
          filename="package://assem_urdf.SLDASM/meshes/FL_Hip5_link.STL" />
      </geometry>
    </collision>
  </link>
  <joint
    name="FL_Hip5_joint"
    type="revolute">
    <origin
      xyz="0.10154 0.051686 -0.010368"
      rpy="0 0 2.0416" />
    <parent
      link="FL_Hip4_link" />
    <child
      link="FL_Hip5_link" />
    <axis
      xyz="0 0 1" />
    <limit
      lower="0"
      upper="0"
      effort="0"
      velocity="0" />
  </joint>
  <link
    name="RR_Hip6_link">
    <inertial>
      <origin
        xyz="-0.00060544 1.2143E-17 -0.034287"
        rpy="0 0 0" />
      <mass
        value="0.067785" />
      <inertia
        ixx="2.6247E-05"
        ixy="7.5985E-23"
        ixz="5.961E-08"
        iyy="3.2333E-05"
        iyz="3.1781E-22"
        izz="1.3621E-05" />
    </inertial>
    <visual>
      <origin
        xyz="0 0 0"
        rpy="0 0 0" />
      <geometry>
        <mesh
          filename="package://assem_urdf.SLDASM/meshes/RR_Hip6_link.STL" />
      </geometry>
      <material
        name="">
        <color
          rgba="0.79216 0.81961 0.93333 1" />
      </material>
    </visual>
    <collision>
      <origin
        xyz="0 0 0"
        rpy="0 0 0" />
      <geometry>
        <mesh
          filename="package://assem_urdf.SLDASM/meshes/RR_Hip6_link.STL" />
      </geometry>
    </collision>
  </link>
  <joint
    name="RR_Hip6_joint"
    type="revolute">
    <origin
      xyz="-0.04 0.285 -0.01025"
      rpy="1.5708 0 3.1416" />
    <parent
      link="base_link" />
    <child
      link="RR_Hip6_link" />
    <axis
      xyz="0 0 1" />
    <limit
      lower="0"
      upper="0"
      effort="0"
      velocity="0" />
  </joint>
  <link
    name="RR_Hip7_link">
    <inertial>
      <origin
        xyz="0.034716961087133 0.0330827435607052 0.00118351028798536"
        rpy="0 0 0" />
      <mass
        value="0.00641061944901924" />
      <inertia
        ixx="6.02291683364987E-06"
        ixy="-3.9420806956738E-06"
        ixz="-2.898185097182E-08"
        iyy="2.679914803784E-06"
        iyz="-4.37682660936721E-08"
        izz="8.66948634202206E-06" />
    </inertial>
    <visual>
      <origin
        xyz="0 0 0"
        rpy="0 0 0" />
      <geometry>
        <mesh
          filename="package://assem_urdf.SLDASM/meshes/RR_Hip7_link.STL" />
      </geometry>
      <material
        name="">
        <color
          rgba="0.792156862745098 0.819607843137255 0.933333333333333 1" />
      </material>
    </visual>
    <collision>
      <origin
        xyz="0 0 0"
        rpy="0 0 0" />
      <geometry>
        <mesh
          filename="package://assem_urdf.SLDASM/meshes/RR_Hip7_link.STL" />
      </geometry>
    </collision>
  </link>
  <joint
    name="RR_Hip7_joint"
    type="revolute">
    <origin
      xyz="0.024669 -0.0089469 -0.036231"
      rpy="-1.5708 -0.98592 -1.5708" />
    <parent
      link="RR_Hip6_link" />
    <child
      link="RR_Hip7_link" />
    <axis
      xyz="0 0 -1" />
    <limit
      lower="0"
      upper="0"
      effort="0"
      velocity="0" />
  </joint>
  <link
    name="RR_Hip8_link">
    <inertial>
      <origin
        xyz="0.0046193 -0.04954 0.0037719"
        rpy="0 0 0" />
      <mass
        value="0.0025827" />
      <inertia
        ixx="3.3136E-06"
        ixy="3.0682E-07"
        ixz="-2.721E-09"
        iyy="5.1611E-08"
        iyz="2.9182E-08"
        izz="3.3606E-06" />
    </inertial>
    <visual>
      <origin
        xyz="0 0 0"
        rpy="0 0 0" />
      <geometry>
        <mesh
          filename="package://assem_urdf.SLDASM/meshes/RR_Hip8_link.STL" />
      </geometry>
      <material
        name="">
        <color
          rgba="0.79216 0.81961 0.93333 1" />
      </material>
    </visual>
    <collision>
      <origin
        xyz="0 0 0"
        rpy="0 0 0" />
      <geometry>
        <mesh
          filename="package://assem_urdf.SLDASM/meshes/RR_Hip8_link.STL" />
      </geometry>
    </collision>
  </link>
  <joint
    name="RR_Hip8_joint"
    type="revolute">
    <origin
      xyz="0.072151 0.089615 0.0038305"
      rpy="0 0 2.4637" />
    <parent
      link="RR_Hip7_link" />
    <child
      link="RR_Hip8_link" />
    <axis
      xyz="0 0 -1" />
    <limit
      lower="0"
      upper="0"
      effort="0"
      velocity="0" />
  </joint>
  <link
    name="RL_Hip9_link">
    <inertial>
      <origin
        xyz="0 0 0"
        rpy="0 0 0" />
      <mass
        value="0" />
      <inertia
        ixx="0"
        ixy="0"
        ixz="0"
        iyy="0"
        iyz="0"
        izz="0" />
    </inertial>
    <visual>
      <origin
        xyz="0 0 0"
        rpy="0 0 0" />
      <geometry>
        <mesh
          filename="package://assem_urdf.SLDASM/meshes/RL_Hip9_link.STL" />
      </geometry>
      <material
        name="">
        <color
          rgba="1 1 1 1" />
      </material>
    </visual>
    <collision>
      <origin
        xyz="0 0 0"
        rpy="0 0 0" />
      <geometry>
        <mesh
          filename="package://assem_urdf.SLDASM/meshes/RL_Hip9_link.STL" />
      </geometry>
    </collision>
  </link>
  <joint
    name="RL_Hip9_joint"
    type="revolute">
    <origin
      xyz="0.04 0.285 -0.01025"
      rpy="-1.5708 0 0" />
    <parent
      link="base_link" />
    <child
      link="RL_Hip9_link" />
    <axis
      xyz="0 0 1" />
    <limit
      lower="0"
      upper="0"
      effort="0"
      velocity="0" />
  </joint>
  <link
    name="RL_Hip10_link">
    <inertial>
      <origin
        xyz="0.041114 0.020928 -0.0077205"
        rpy="0 0 0" />
      <mass
        value="0.0064106" />
      <inertia
        ixx="1.8319E-06"
        ixy="-3.4621E-06"
        ixz="4.6782E-08"
        iyy="6.8709E-06"
        iyz="2.3813E-08"
        izz="8.6695E-06" />
    </inertial>
    <visual>
      <origin
        xyz="0 0 0"
        rpy="0 0 0" />
      <geometry>
        <mesh
          filename="package://assem_urdf.SLDASM/meshes/RL_Hip10_link.STL" />
      </geometry>
      <material
        name="">
        <color
          rgba="0.79216 0.81961 0.93333 1" />
      </material>
    </visual>
    <collision>
      <origin
        xyz="0 0 0"
        rpy="0 0 0" />
      <geometry>
        <mesh
          filename="package://assem_urdf.SLDASM/meshes/RL_Hip10_link.STL" />
      </geometry>
    </collision>
  </link>
  <joint
    name="RL_Hip10_joint"
    type="continuous">
    <origin
      xyz="0.018132 0.0095637 -0.02555"
      rpy="-1.5708 -0.47085 1.5708" />
    <parent
      link="RL_Hip9_link" />
    <child
      link="RL_Hip10_link" />
    <axis
      xyz="0 0 1" />
  </joint>
  <link
    name="RL_Hip11_link">
    <inertial>
      <origin
        xyz="-1.1102E-16 -0.049755 -0.0037719"
        rpy="0 0 0" />
      <mass
        value="0.0025827" />
      <inertia
        ixx="3.3422E-06"
        ixy="-6.2995E-21"
        ixz="-5.6744E-23"
        iyy="2.3002E-08"
        iyz="-2.9308E-08"
        izz="3.3606E-06" />
    </inertial>
    <visual>
      <origin
        xyz="0 0 0"
        rpy="0 0 0" />
      <geometry>
        <mesh
          filename="package://assem_urdf.SLDASM/meshes/RL_Hip11_link.STL" />
      </geometry>
      <material
        name="">
        <color
          rgba="0.79216 0.81961 0.93333 1" />
      </material>
    </visual>
    <collision>
      <origin
        xyz="0 0 0"
        rpy="0 0 0" />
      <geometry>
        <mesh
          filename="package://assem_urdf.SLDASM/meshes/RL_Hip11_link.STL" />
      </geometry>
    </collision>
  </link>
  <joint
    name="RL_Hip11_joint"
    type="revolute">
    <origin
      xyz="0.10154 0.051686 -0.010368"
      rpy="0 0 2.0416" />
    <parent
      link="RL_Hip10_link" />
    <child
      link="RL_Hip11_link" />
    <axis
      xyz="0 0 1" />
    <limit
      lower="0"
      upper="0"
      effort="0"
      velocity="0" />
  </joint>
</robot>